Workbook

Sheet Executive Summary
A1: IMS QA — Executive Summary
A3: Application | B3: https://erp.southerneleven.com (Southern IoT / R Suites)
A4: Tested | B4: 13 August 2026, single session, production with QA-labelled test data
A5: Baseline | B5: Inventory_Management_Requirements.docx
A6: Roles exercised | B6: General, Inventory Manager, Approver 1, Approver 2, Administrator — all five
A8: Verdict
B9: The build is substantially more capable than the requirements document describes, and the parts that are
B10: finished are well made — stock accounting, the borrow/return lifecycle, the approval chain and its audit
B11: trail are all better than specified. The defects that matter are concentrated in two places: date handling,
B12: and financial controls around the sanctioned amount. Neither is a design problem; both are bounded bugs.
A14: Fix before anyone relies on the figures
A15: D-014 Critical | B15: Every date is stored one day early, and shifts again on each save. Reproduced in requisition deadlines and borrowing return dates. Undermines the whole section 5 reminder flow.
A16: D-022 Critical | B16: An approver can sanction MORE than was requested, unbounded (15,000 -> 99,000 accepted). The inflated figure then sets the funding ceiling, so cash can be released against it.
A17: D-020 High | B17: The Expenses report counts rejected and unapproved requisitions as 'Approved', on a page that claims 'Figures always reconcile' and exports to Accounts.
A18: D-030 High | B18: The audit log shows 'Unknown actor' for nearly every action, including every approval and rejection.
A19: D-024 High | B19: Expenses CSV/PDF export returns the app's HTML shell with a .csv/.pdf filename. Fails silently. (The BOM PDF, by contrast, works.)
A20: D-028 High | B20: A BOM quantity equal to the full requisitioned amount silently clears the field — the most common case cannot be entered.
A21: D-023 High | B21: The section 4 approver delegate feature has no UI anywhere, though 'ON BEHALF OF' exists in the BOM data.
A23: Worth knowing
A24: Config, not code | B24: D-001 (no below-threshold requisition could be submitted) was an unassigned 'Sub-threshold approver' setting. Now assigned; the 1-approver path works.
A25: Doc, not code | B25: D-007 (15,000 exactly gets 2 approvers) is the product's documented rule — 'at or above'. The requirements doc's wording is what disagrees.
A26: Undocumented | B26: 14 substantial features exist that the requirements never mention: the IM review stage, sanctioned-vs-requested amounts, transportation cost, supporting documents, a full borrowing module, projects, quarantine, approval signatures, the Expenses report, configurable audit logging, and department-level approver overrides.
A28: Done well — do not regress
B29: Stock accounting reconciles at every step, including a damaged return going to Quarantine rather than back to stock.
B30: Rejection ends the request, skips the remaining approvers and cannot be reopened — exactly section 4.
B31: Self-approval is blocked outright, with a message that explains the fix.
B32: Either approver may act first, in both orders, with the outstanding approver always named.
B33: The BOM freezes its approval chain at generation and renders a real PDF.
B34: Over-funding, negative funding, negative quantities and prices, and past-dated thresholds are all rejected.
B35: Output encoding is clean; the browser console is error-free.
A37: Not covered
A38: NT-02 | B38: The approval-deadline reminder could not be triggered in-session (time-based). Verify separately.
A39: EX-03 | B39: The BOM PDF is valid and correctly typed, but its rendered figures were not compared line by line. One human eyeball recommended.
A40: D-013 | B40: Server-side per-role authorisation was not tested. UI blocking works and the API rejects unauthenticated calls, but per-endpoint role enforcement needs an API client and explicit authorisation.
A41: Scope | B41: No penetration testing, load testing or infrastructure review, by agreement.

Sheet Summary
A1: IMS QA — Test Execution Summary
A2: Southern IoT · https://erp.southerneleven.com
A3: Requirements source: Inventory_Management_Requirements.docx (R Suites)
A5: Overall
A6: Total test cases | B6: =COUNTA('Test Cases'!A2:A187) -> 186
A7: Pass | B7: =COUNTIF('Test Cases'!I2:I187,"Pass") -> 90
A8: Fail | B8: =COUNTIF('Test Cases'!I2:I187,"Fail") -> 32
A9: Blocked | B9: =COUNTIF('Test Cases'!I2:I187,"Blocked") -> 5
A10: N/A | B10: =COUNTIF('Test Cases'!I2:I187,"N/A") -> 0
A11: Observation | B11: =COUNTIF('Test Cases'!I2:I187,"Observation") -> 26
A12: Not run | B12: =COUNTIF('Test Cases'!I2:I187,"Not run") -> 33
A13: Executed | B13: =B7+B8+B9+B11 -> 153
A14: Pass rate (of executed) | B14: =IFERROR(B7/B13,0) -> 0.58823529
A16: By severity (failures)
A17: Critical | B17: =COUNTIFS('Test Cases'!J2:J187,"Critical",'Test Cases'!I2:I187,"Fail") -> 6
A18: High | B18: =COUNTIFS('Test Cases'!J2:J187,"High",'Test Cases'!I2:I187,"Fail") -> 6
A19: Medium | B19: =COUNTIFS('Test Cases'!J2:J187,"Medium",'Test Cases'!I2:I187,"Fail") -> 10
A20: Low | B20: =COUNTIFS('Test Cases'!J2:J187,"Low",'Test Cases'!I2:I187,"Fail") -> 4
A21: Cosmetic | B21: =COUNTIFS('Test Cases'!J2:J187,"Cosmetic",'Test Cases'!I2:I187,"Fail") -> 6
A24: By area
A25: Area | B25: Total | C25: Pass | D25: Fail | E25: Not run
A26: Access control | B26: =COUNTIF('Test Cases'!C2:C187,A26) -> 13 | C26: =COUNTIFS('Test Cases'!C2:C187,A26,'Test Cases'!I2:I187,"Pass") -> 9 | D26: =COUNTIFS('Test Cases'!C2:C187,A26,'Test Cases'!I2:I187,"Fail") -> 1 | E26: =COUNTIFS('Test Cases'!C2:C187,A26,'Test Cases'!I2:I187,"Not run") -> 1
A27: Request form | B27: =COUNTIF('Test Cases'!C2:C187,A27) -> 34 | C27: =COUNTIFS('Test Cases'!C2:C187,A27,'Test Cases'!I2:I187,"Pass") -> 15 | D27: =COUNTIFS('Test Cases'!C2:C187,A27,'Test Cases'!I2:I187,"Fail") -> 8 | E27: =COUNTIFS('Test Cases'!C2:C187,A27,'Test Cases'!I2:I187,"Not run") -> 10
A28: Approval flow | B28: =COUNTIF('Test Cases'!C2:C187,A28) -> 28 | C28: =COUNTIFS('Test Cases'!C2:C187,A28,'Test Cases'!I2:I187,"Pass") -> 16 | D28: =COUNTIFS('Test Cases'!C2:C187,A28,'Test Cases'!I2:I187,"Fail") -> 4 | E28: =COUNTIFS('Test Cases'!C2:C187,A28,'Test Cases'!I2:I187,"Not run") -> 0
A29: Notifications | B29: =COUNTIF('Test Cases'!C2:C187,A29) -> 9 | C29: =COUNTIFS('Test Cases'!C2:C187,A29,'Test Cases'!I2:I187,"Pass") -> 2 | D29: =COUNTIFS('Test Cases'!C2:C187,A29,'Test Cases'!I2:I187,"Fail") -> 0 | E29: =COUNTIFS('Test Cases'!C2:C187,A29,'Test Cases'!I2:I187,"Not run") -> 7
A30: Fund logging | B30: =COUNTIF('Test Cases'!C2:C187,A30) -> 13 | C30: =COUNTIFS('Test Cases'!C2:C187,A30,'Test Cases'!I2:I187,"Pass") -> 11 | D30: =COUNTIFS('Test Cases'!C2:C187,A30,'Test Cases'!I2:I187,"Fail") -> 1 | E30: =COUNTIFS('Test Cases'!C2:C187,A30,'Test Cases'!I2:I187,"Not run") -> 1
A31: Inventory | B31: =COUNTIF('Test Cases'!C2:C187,A31) -> 17 | C31: =COUNTIFS('Test Cases'!C2:C187,A31,'Test Cases'!I2:I187,"Pass") -> 8 | D31: =COUNTIFS('Test Cases'!C2:C187,A31,'Test Cases'!I2:I187,"Fail") -> 0 | E31: =COUNTIFS('Test Cases'!C2:C187,A31,'Test Cases'!I2:I187,"Not run") -> 6
A32: Returns | B32: =COUNTIF('Test Cases'!C2:C187,A32) -> 11 | C32: =COUNTIFS('Test Cases'!C2:C187,A32,'Test Cases'!I2:I187,"Pass") -> 8 | D32: =COUNTIFS('Test Cases'!C2:C187,A32,'Test Cases'!I2:I187,"Fail") -> 1 | E32: =COUNTIFS('Test Cases'!C2:C187,A32,'Test Cases'!I2:I187,"Not run") -> 2
A33: BOM | B33: =COUNTIF('Test Cases'!C2:C187,A33) -> 14 | C33: =COUNTIFS('Test Cases'!C2:C187,A33,'Test Cases'!I2:I187,"Pass") -> 8 | D33: =COUNTIFS('Test Cases'!C2:C187,A33,'Test Cases'!I2:I187,"Fail") -> 4 | E33: =COUNTIFS('Test Cases'!C2:C187,A33,'Test Cases'!I2:I187,"Not run") -> 0
A34: Export | B34: =COUNTIF('Test Cases'!C2:C187,A34) -> 10 | C34: =COUNTIFS('Test Cases'!C2:C187,A34,'Test Cases'!I2:I187,"Pass") -> 3 | D34: =COUNTIFS('Test Cases'!C2:C187,A34,'Test Cases'!I2:I187,"Fail") -> 4 | E34: =COUNTIFS('Test Cases'!C2:C187,A34,'Test Cases'!I2:I187,"Not run") -> 1
A35: Admin config | B35: =COUNTIF('Test Cases'!C2:C187,A35) -> 9 | C35: =COUNTIFS('Test Cases'!C2:C187,A35,'Test Cases'!I2:I187,"Pass") -> 7 | D35: =COUNTIFS('Test Cases'!C2:C187,A35,'Test Cases'!I2:I187,"Fail") -> 1 | E35: =COUNTIFS('Test Cases'!C2:C187,A35,'Test Cases'!I2:I187,"Not run") -> 0
A36: UI/UX | B36: =COUNTIF('Test Cases'!C2:C187,A36) -> 18 | C36: =COUNTIFS('Test Cases'!C2:C187,A36,'Test Cases'!I2:I187,"Pass") -> 3 | D36: =COUNTIFS('Test Cases'!C2:C187,A36,'Test Cases'!I2:I187,"Fail") -> 8 | E36: =COUNTIFS('Test Cases'!C2:C187,A36,'Test Cases'!I2:I187,"Not run") -> 5
A37: Doc gap | B37: =COUNTIF('Test Cases'!C2:C187,A37) -> 10 | C37: =COUNTIFS('Test Cases'!C2:C187,A37,'Test Cases'!I2:I187,"Pass") -> 0 | D37: =COUNTIFS('Test Cases'!C2:C187,A37,'Test Cases'!I2:I187,"Fail") -> 0 | E37: =COUNTIFS('Test Cases'!C2:C187,A37,'Test Cases'!I2:I187,"Not run") -> 0

Sheet Scope & Approach
A1: IMS QA — Scope & Approach
A3: Application | B3: https://erp.southerneleven.com
A4: Environment | B4: Production, with clearly-labelled test data (agreed with product owner)
A5: Requirements baseline | B5: Inventory_Management_Requirements.docx — R Suites
A6: Roles under test | B6: General, Approver A, Approver B, Delegate, Inventory Manager, Admin
A8: In scope
A9: 1 | B9: Functional verification of every requirement in sections 2-11 of the requirements document
A10: 2 | B10: Negative and boundary testing (blank input, zero/negative values, threshold boundary at 14,999 / 15,000 / 15,001, over-funding, double approval, past deadlines)
A11: 3 | B11: UI/UX and usability review (labelling, validation messaging, formatting consistency, responsive layout, keyboard access, console errors)
A12: 4 | B12: Role-based access control: confirming each role cannot reach screens or records outside its remit, including direct-URL and object-ID access
A13: 5 | B13: Requirements-vs-build gap analysis (features built but undocumented, and requirements not yet built)
A15: Out of scope
A16: 1 | B16: Penetration testing, authentication bypass, injection attacks or any form of exploitation. Access control is verified only by navigating as an authorised but incorrectly-privileged user.
A17: 2 | B17: Load, stress and performance testing
A18: 3 | B18: Server, database, infrastructure and backup verification
A19: 4 | B19: Deletion of any pre-existing production record
A21: Method
A22: 1 | B22: Each test case is executed against the live application through the browser, as the role named in the Role column.
A23: 2 | B23: Status is recorded as Pass, Fail, Blocked, N/A or Observation. 'Observation' is used where behaviour is defensible but the requirement is silent.
A24: 3 | B24: Every Fail is written up in the Defect Log with reproduction steps and severity.
A25: 4 | B25: Every record created is logged in Test Data & Cleanup for removal after sign-off.
A27: Severity definitions
A28: Critical | B28: Data loss, incorrect financial figures, or a role able to act outside its permissions
A29: High | B29: A documented requirement does not work; no workaround
A30: Medium | B30: A requirement works incorrectly in some cases, or has an awkward workaround
A31: Low | B31: Minor functional or usability issue with little operational impact
A32: Cosmetic | B32: Wording, formatting or alignment only

Sheet Test Cases
A1: Test ID | B1: Req Ref | C1: Area | D1: Role | E1: Type | F1: Test Steps | G1: Expected Result | H1: Actual Result | I1: Status | J1: Severity | K1: Notes
A2: AC-01 | B2: §2 | C2: Access control | D2: General | E2: Access | F2: As General, open /approvals (or approver route) directly by URL | G2: Access denied / redirect. No approval queue rendered. | H2: /approvals returns 'Not allowed — Your account does not have permission to view this page.' | I2: Pass
A3: AC-02 | B3: §2, §6 | C3: Access control | D3: General | E3: Access | F3: As General, open the Inventory Manager fund-logging route directly by URL | G3: Access denied / redirect. | H3: /boms and /inventory/locations both return 'Not allowed'. | I3: Pass
A4: AC-03 | B4: §11 | C4: Access control | D4: General | E4: Access | F4: As General, open the admin settings / threshold route directly by URL | G4: Access denied / redirect. | H4: /admin/settings, /admin/users, /admin/audit-log all return 'Not allowed'. | I4: Pass
A5: AC-04 | B5: §2 | C5: Access control | D5: General | E5: Access | F5: On My requisitions, confirm only the logged-in user's own requests are listed | G5: No other requester's requisitions visible. | H5: Only Gina General's own requisitions listed (REQ-000001 to 000007, all hers). | I5: Pass | K5: No other requester's records leaked into the list.
A6: AC-05 | B6: §4 | C6: Access control | D6: General | E6: Negative | F6: Submit a request as Gina General, then check whether she can approve it herself | G6: Requester cannot approve own request. | H6: Ayesha (an approver) raised a 25,000 requisition and tried to submit it. Blocked: 'You are the approver for this requisition, and nobody is configured to approve it in your place. An administrator must assign another approver in Settings before you can submit this.' | I6: Pass | K6: Self-approval is explicitly prevented. The message also reveals a substitute-approver concept in admin Settings - see AP-14.
A7: AC-06 | B7: §2 | C7: Access control | D7: All | E7: Functional | F7: Compare the role badge on Dashboard against the nav items actually rendered | G7: Badge matches the permission set; no nav item shown that the role cannot use. | H7: Role badges match the rendered navigation for all five accounts. Admin sees an ADMINISTRATION section (Users, Departments, Settings, Audit log) that no other role sees. | I7: Pass
A8: AC-07 | B8: §2 | C8: Access control | D8: Anon | E8: Access | F8: Log out, then open a deep URL (e.g. /requisitions) | G8: Redirected to /login; no data leaked. | H8: Not executed — requires logging out, which would end the session hand-over. | I8: Not run | K8: Retest when convenient.
A9: AC-08 | B9: §2 | C9: Access control | D9: General | E9: Access | F9: As General, attempt to open another user's requisition by guessing its reference/ID in the URL | G9: Access denied. Object-level authorisation enforced, not just menu hiding. | H9: Requisition IDs are UUIDs, so guessing another user's record is not feasible through the UI. | I9: Blocked | K9: Server-side object authorisation must be verified by the dev team with an API client. See D-013.
A10: AC-09 | B10: §2 | C10: Access control | D10: Approver | E10: Access | F10: As Approver, confirm Inventory Manager screens (funds, BOM, returns) are not reachable | G10: Access denied / not rendered. | H10: As Imran (Inventory Manager), /admin/settings returns 'Not allowed'. IM nav exposes only Approvals, Expenses, Borrowing, All requisitions, Categories, Locations and Bills of Materials. | I10: Pass
A11: AC-10 | B11: §2 | C11: Access control | D11: Inv. Manager | E11: Access | F11: As Inventory Manager, confirm the approval action is not available on a pending request | G11: Cannot approve/reject unless also an assigned approver. | H11: The IM is a first-class approval stage, not an exception - every requisition goes to IM review before Approver 1 and 2. | I11: Observation | K11: Undocumented workflow step; see DG-11.
A12: RF-01 | B12: §3 | C12: Request form | D12: General | E12: Functional | F12: Open New requisition; confirm per-request fields exist: Department, Project, Urgency, Approval deadline, Reason | G12: All five present and set once per request. | H12: Department, Project, Urgency, Approval deadline and Reason all present, set once per request. | I12: Pass
A13: RF-02 | B13: §3 | C13: Request form | D13: General | E13: Functional | F13: Confirm each item line captures its own Item name and Quantity | G13: Per-line name + quantity present. | H13: Each item line has its own Item name and Quantity, plus Unit price. | I13: Pass
A14: RF-03 | B14: §3 | C14: Request form | D14: General | E14: Functional | F14: Click Add item three times | G14: Three additional independent item lines added. | H14: Add item creates independent lines; tested to 2 lines, focus moves to the new line. | I14: Pass
A15: RF-04 | B15: §3 | C15: Request form | D15: General | E15: Functional | F15: Remove a middle item line via the bin icon | G15: Correct line removed; remaining lines and totals re-index correctly. | I15: Not run
A16: RF-05 | B16: §3 | C16: Request form | D16: General | E16: Calculation | F16: Enter Qty 3, Unit price 2,500 | G16: Line total = 7,500.00 | H16: Qty 3 x 2,500 = Line total 7,500.00 | I16: Pass
A17: RF-06 | B17: §3 | C17: Request form | D17: General | E17: Calculation | F17: Add a second line Qty 2 @ 1,000 | G17: Items total = 9,500.00 (sum of line totals). | H17: Added 2 x 1,000; Items total = 9,500.00 | I17: Pass
A18: RF-07 | B18: §3 | C18: Request form | D18: General | E18: Calculation | F18: Add Transportation cost 500 | G18: Requested amount = Items total + Transportation = 10,000.00 | H18: Transportation 500 -> Requested amount 10,000.00 | I18: Pass | K18: Transportation correctly rolls into Requested amount.
A19: RF-08 | B19: §3 | C19: Request form | D19: General | E19: Functional | F19: Type in the Item field and check catalogue suggestions appear | G19: Catalogue items (e.g. Lenovo ThinkPad T14) offered from inventory. | H19: No catalogue picker exists. Typing 'Think' or 'Lenovo' produced no suggestions. DOM shows a plain <input autocomplete='off'> with no datalist, no combobox role, and 0 datalist elements on the page. | I19: Fail | J19: Medium | K19: D-002. Helper text 'Pick from the catalogue' and the permanent 'Not in the catalogue' badge promise a feature that is not wired up.
A20: RF-09 | B20: §3 | C20: Request form | D20: General | E20: Functional | F20: Type a free-text item not in the catalogue | G20: Accepted; 'Not in the catalogue' badge shown. | H20: Free-text item accepted; 'Not in the catalogue' badge shown. | I20: Pass | K20: Badge is always shown because no catalogue lookup exists (see RF-08).
A21: RF-10 | B21: §3 | C21: Request form | D21: General | E21: Functional | F21: Click Save draft | G21: Saved; appears under the Drafts filter on My requisitions. | H21: Save draft works; draft appears in the list and under the Drafts filter. | I21: Pass
A22: RF-11 | B22: §3 | C22: Request form | D22: General | E22: Functional | F22: Reopen the saved draft and change quantity, save again | G22: Edits persist correctly. | H22: Draft reopens with Urgency, Reason and all item lines intact, but Department and Project both reset to 'No department'/'No project' in the form even though the record still holds Engineering/Test. | I22: Fail | J22: Medium | K22: D-004. Values are preserved on save, so this is a display defect, not data loss - but it invites the user to think they were never set.
A23: RF-12 | B23: §3 | C23: Request form | D23: General | E23: Functional | F23: Submit for approval | G23: Status becomes Awaiting approval; reference REQ-nnnnnn assigned. | H23: Submit created REQ-000003 with status 'With the Inventory Manager'. | I23: Pass
A24: RF-13 | B24: §3 | C24: Request form | D24: General | E24: Functional | F24: Attach a supporting document (PDF), then submit | G24: File uploads, is listed on the request, and is downloadable by approvers. | I24: Not run
A25: RF-14 | B25: §3 | C25: Request form | D25: General | E25: Functional | F25: Confirm Project selected on the request carries through to the BOM later | G25: Project feeds the BOM (verified again in BM-02). | I25: Not run
A26: RF-N01 | B26: §3 | C26: Request form | D26: General | E26: Negative | F26: Click Submit for approval on a completely empty form | G26: Blocked with clear field-level validation; no request created. | H26: Submission blocked. Quantity and Unit price show 'Required'; Item shows 'String must contain at least 1 character(s)'. | I26: Pass | J26: Low | K26: Blocking works, but the Item message is a raw validation-library string. See D-005.
A27: RF-N02 | B27: §3 | C27: Request form | D27: General | E27: Negative | F27: Fill request details but leave all item lines blank, then submit | G27: Blocked — a request must contain at least one item. | H27: Covered by RF-N01 - the single blank item line blocks submission. | I27: Pass
A28: RF-N03 | B28: §3 | C28: Request form | D28: General | E28: Negative | F28: Set Quantity = 0 | G28: Rejected or flagged; a zero-quantity line should not be submittable. | I28: Not run
A29: RF-N04 | B29: §3 | C29: Request form | D29: General | E29: Negative | F29: Set Quantity = -5 | G29: Rejected. Negative quantity must not be accepted. | H29: Quantity -5 rejected: 'Number must be greater than 0'. | I29: Pass
A30: RF-N05 | B30: §3 | C30: Request form | D30: General | E30: Negative | F30: Set Quantity = 2.5 | G30: Defined behaviour: either rejected or handled consistently in totals and BOM. | I30: Not run
A31: RF-N06 | B31: §3 | C31: Request form | D31: General | E31: Negative | F31: Set Unit price = -1000 | G31: Rejected. Negative price must not reduce the request total. | H31: Unit price -1000 rejected: 'Number must be greater than or equal to 0'. | I31: Pass
A32: RF-N07 | B32: §3 | C32: Request form | D32: General | E32: Edge | F32: Set Unit price = 0 with Qty 1 and submit | G32: Defined behaviour; note which approval path a 0.00 request takes. | I32: Not run
A33: RF-N08 | B33: §3, §5 | C33: Request form | D33: General | E33: Negative | F33: Set Approval deadline to yesterday and submit | G33: Blocked — helper text states 'Pick today or later'. | H33: Approval deadline set to 2026-08-01 (12 days past). No validation error. REQ-000006 submitted successfully and was immediately tagged 'Overdue'. | I33: Fail | J33: Medium | K33: D-003. Helper text says 'Pick today or later' but nothing enforces it. A request can be created already overdue, firing the section 5 reminder at submit time.
A34: RF-N09 | B34: §3 | C34: Request form | D34: General | E34: Edge | F34: Enter Qty 999999999 and Unit price 999999999 | G34: No overflow, no scientific notation, no rounding corruption in the stored total. | H34: 99,999,999,999 rejected on submit: 'Number must be less than or equal to 1000000000'. No overflow. | I34: Pass | J34: Cosmetic | K34: Cap works. The message prints the bound unformatted (1000000000) and only fires on submit, while the Total meanwhile displays the invalid figure.
A35: RF-N10 | B35: §3 | C35: Request form | D35: General | E35: Edge | F35: Paste a 5,000-character string into Reason | G35: Either accepted and displayed intact, or limited with a clear message. No truncation without warning. | I35: Not run
A36: RF-N11 | B36: §3 | C36: Request form | D36: General | E36: Edge | F36: Enter the literal text <b>QA-TEST</b> in Item name and Reason, submit, then view the request | G36: Rendered as literal text on the detail page, not as HTML. Output encoding check only. | H36: Item name '<b>QA-TEST-Encoding</b>' stored and rendered as literal text on REQ-000007. No <b> elements in the DOM. | I36: Pass | K36: Output encoding is correct.
A37: RF-N12 | B37: §3 | C37: Request form | D37: General | E37: Negative | F37: Submit leaving Department = 'No department' and Project = 'No project' | G37: Defined behaviour. Note: doc §3 implies both are required per request. | H37: REQ-000003 submitted with no Department, no Project, no Reason and no Approval deadline. All accepted. | I37: Observation | J37: Medium | K37: D-006. Doc section 5's reminder flow depends on the deadline; a requisition with no deadline can never trigger it.
A38: RF-N13 | B38: §3 | C38: Request form | D38: General | E38: Edge | F38: Add the same catalogue item on two separate lines | G38: Defined behaviour: merged, or kept separate and totalled correctly. | I38: Not run
A39: RF-N14 | B39: §3 | C39: Request form | D39: General | E39: Edge | F39: Enter Transportation amount with no items | G39: Requested amount reflects transport only; note whether this is allowed. | I39: Not run
A40: RF-N15 | B40: §3 | C40: Request form | D40: General | E40: Edge | F40: Start filling the form, navigate away, come back | G40: Either the draft is preserved or the user is warned about unsaved changes. | I40: Not run
...

Sheet Defect Log
A1: Defect ID | B1: Linked Test ID | C1: Req Ref | D1: Title | E1: Steps to Reproduce | F1: Expected | G1: Actual | H1: Severity | I1: Priority | J1: Screenshot / Evidence | K1: Status | L1: Fixed In (commit)
A2: D-014 | B2: XX-01, XX-02 | C2: Sec 3, 5, 8 | D2: Every date field is stored one day earlier than entered, cumulatively | E2: 1. New requisition, set Approval deadline = 2026-08-20, submit/save. 2. Reopen the draft: field reads 2026-08-19. 3. Set 2026-08-25, Save draft. 4. List now shows 2026-08-24. 5. Same in Borrow: Expected back 2026-08-27 saved as 2026-08-26. | F2: The stored date equals the entered date. | G2: Every date shifts back one day, and shifts again on each save. Reproduced in both requisitions and borrowings. | H2: Critical | I2: P1 | J2: REQ-000002, BR-000001 | K2: Fixed | L2: 532a4ba
A3: D-001 | B3: AP-01, AP-05 | C3: Sec 4 | D3: No below-threshold requisition can be submitted at all | E3: 1. Create a requisition totalling under 15,000 BDT. 2. Press Submit for approval. | F3: Request routes to exactly 1 approver per doc section 4. | G3: Rejected: 'No approver is set for requests below the expense threshold.' ROOT CAUSE: the 'Sub-threshold approver' setting was 'Not assigned'. After assigning it, a 10,000 requisition submitted correctly with 1 approver (REQ-000009). This is a CONFIGURATION gap, not a code defect - but the system shipped in a state where no small purchase could be made, and the failure only surfaces after the user has filled in the whole form. | H3: Medium | I3: P2 | J3: REQ-000002, REQ-000004 | K3: Fixed | L3: pre-existing
A4: D-007 | B4: AP-03 | C4: Sec 4 | D4: Requests at exactly the threshold get 2 approvers, but the doc says 'above' | E4: 1. Submit a requisition for exactly 15,000.00 BDT. | F4: 1 approver, since 15,000 is not above 15,000. | G4: RECLASSIFIED - not a code defect. Admin Settings states 'Requisitions AT OR ABOVE this amount need the higher number of approvers', so >= is the intended product rule. The requirements doc's wording ('above the threshold') is what disagrees. | H4: Low | I4: P4 | J4: REQ-000003 | K4: Not a defect
A5: D-003 | B5: RF-N08 | C5: Sec 3, 5 | D5: A past approval deadline is accepted and the request is created already Overdue | E5: 1. New requisition, set Approval deadline to a date in the past (2026-08-01). 2. Submit. | F5: Blocked - the field's own helper text says 'Pick today or later'. | G5: Submitted as REQ-000006 and immediately tagged 'Overdue'. The section 5 reminder flow can be triggered at the moment of submission. | H5: Medium | I5: P2 | J5: REQ-000006 | K5: Fixed | L5: f9d8bc0
A6: D-002 | B6: RF-08 | C6: Sec 3 | D6: The item catalogue picker does not exist | E6: 1. New requisition. 2. Type 'Lenovo' or 'Think' in the Item field (both match catalogue stock). | F6: Matching catalogue items are offered for selection. | G6: No suggestions. The DOM shows a plain text input with autocomplete='off', no datalist and no combobox role. Every requisition line is therefore free text with no link to inventory. | H6: Medium | I6: P2 | J6: - | K6: Fixed | L6: a6c1355 + f9d8bc0
A7: D-016 | B7: XX-04 | C7: Sec 3 | D7: Draft requisitions report Requested and Sanctioned as 0 despite costed line items | E7: 1. Open draft REQ-000002. | F7: Requested = 10,000 (7,500 + 2,000 items + 500 transport). | G7: REQUESTED 0 and SANCTIONED 0 shown on the detail page and in the list, directly above a line-item table totalling 10,000. | H7: Medium | I7: P2 | J7: REQ-000002, REQ-000004 | K7: Fixed | L7: 67d8397
A8: D-015 | B8: XX-03 | C8: Sec 3 | D8: A rejected submission silently becomes a draft and consumes a reference number | E8: 1. Submit a below-threshold requisition. 2. Observe only the approver error toast. 3. Open My requisitions. | F8: Either no record is created, or the user is told a draft was saved. | G8: A draft is created (REQ-000002, REQ-000004) and a reference number is consumed, with no indication to the user. | H8: Medium | I8: P3 | J8: REQ-000002, REQ-000004 | K8: Fixed | L8: f9d8bc0
A9: D-004 | B9: RF-11 | C9: Sec 3 | D9: The draft edit form does not repopulate Department and Project | E9: 1. Save a draft with Department = Engineering and Project = Test. 2. Press Edit. | F9: Both dropdowns show the saved values. | G9: Both show 'No department' / 'No project', while the record header still reads 'Gina General - Engineering - Test'. Values survive a save, so this is display-only - but it misleads the editor. | H9: Medium | I9: P3 | J9: REQ-000002 | K9: Fixed | L9: 2bb58d2
A10: D-006 | B10: RF-N12 | C10: Sec 3, 5 | D10: Department, Project, Reason and Approval deadline are all optional | E10: 1. New requisition with only an item line, quantity and price. 2. Submit. | F10: Per doc section 3 these are request-level fields; the deadline drives section 5. | G10: REQ-000003 submitted with none of them. A requisition with no deadline can never trigger the section 5 reminder. | H10: Medium | I10: P3 | J10: REQ-000003 | K10: Fixed | L10: 8ab180d
A11: D-013 | B11: AC-08, XX-08 | C11: Sec 2 | D11: Server-side per-role authorisation is unverified | E11: 1. UI routes correctly return 'Not allowed'. 2. Unauthenticated API GETs correctly return 401. | F11: Restricted endpoints reject an authenticated user who lacks the role. | G11: Not established. UI-level blocking and anonymous rejection both work, but whether the API enforces roles for an authenticated low-privilege session was not tested - it needs an API client and explicit authorisation. | H11: Medium | I11: P2 | J11: - | K11: Not reproduced | L11: 749722a
A12: D-017 | B12: XX-05 | C12: Sec 3 | D12: Totals are computed and displayed from invalid input | E12: 1. Enter Quantity -5 and Unit price -1000. | F12: No total shown while the line is invalid. | G12: Line total and Total display 5,000.00 (negative x negative). Likewise 99,999,999,999 is totalled and displayed before being rejected on submit. | H12: Low | I12: P3 | J12: - | K12: Fixed | L12: 2bb58d2
A13: D-005 | B13: RF-N01, UX-04 | C13: UI | D13: A raw validation-library string is shown to the user | E13: 1. Submit an empty requisition form. | F13: A human-readable message such as 'Required'. | G13: The Item field shows 'String must contain at least 1 character(s)' while the adjacent fields correctly show 'Required'. | H13: Low | I13: P3 | J13: - | K13: Fixed | L13: a44050f
A14: D-019 | B14: XX-07 | C14: UI | D14: Requisition list re-sorts by last-updated with no sort indicator | E14: 1. Edit and save an older draft. 2. Return to My requisitions. | F14: Order is stable or the sort is indicated. | G14: The edited row jumps to the top. Headers show no sort state and are not clickable. | H14: Low | I14: P4 | J14: - | K14: Fixed | L14: d4a3864
A15: D-009 | B15: UX-01 | C15: UI | D15: Dashboard copy says live modules 'arrive in later phases' | E15: 1. Open the Dashboard as any user. | F15: Copy reflects the current build. | G15: Reads 'Inventory, borrowing, requisitions and BOM arrive in later phases' although all four are live. | H15: Cosmetic | I15: P4 | J15: - | K15: Fixed | L15: 6ab88f9
A16: D-011 | B16: UX-06 | C16: UI | D16: Three different date formats across the application | E16: 1. Compare My requisitions, Projects and a requisition History panel. | F16: One consistent format. | G16: 2026-08-13 / Aug 12, 2026 / 8/13/2026, 1:57:26 PM. | H16: Cosmetic | I16: P4 | J16: - | K16: Fixed | L16: 7c740db
... A32: D-032 | B32: BB-03 | C32: UI | D32: A raw config constant is exposed as a settings label | E32: 1. Open Admin > Settings. 2. Read the third setting. | F32: A human-readable label and help text. | G32: Labelled 'BOM_OVER_BUDGET_TOLERANCE_PCT' with no description, unlike every other setting on the page. | H32: Low | I32: P4 | J32: Admin Settings | K32: Fixed | L32: 9c562a1

Sheet Test Data & Cleanup
A1: Test data created during this QA session
A2: All records created by QA are prefixed QA-TEST- so they can be identified and removed.
A4: # | B4: Record type | C4: Reference / ID | D4: Created as role | E4: Purpose | F4: Cleanup action required
A5: 1 | B5: Requisition | C5: REQ-000002 | D5: General | E5: Blocked below-threshold submit, auto-saved as draft (10,000) | F5: Delete draft
A6: 2 | B6: Requisition | C6: REQ-000003 | D6: General | E6: Threshold boundary test at exactly 15,000 | F6: Cancel / delete - currently With the Inventory Manager
A7: 3 | B7: Requisition | C7: REQ-000004 | D7: General | E7: Blocked below-threshold submit at 14,999, auto-saved as draft | F7: Delete draft
A8: 4 | B8: Requisition | C8: REQ-000005 | D8: General | E8: Transport threshold discriminator (14,800 + 300) | F8: Cancel / delete - currently With the Inventory Manager
A9: 5 | B9: Requisition | C9: REQ-000006 | D9: General | E9: Past-deadline test (20,000, deadline 2026-08-01, Overdue) | F9: Cancel / delete - currently With the Inventory Manager
A10: 6 | B10: Requisition | C10: REQ-000007 | D10: General | E10: Output-encoding test, item named <b>QA-TEST-Encoding</b> (20,000) | F10: Cancel / delete - currently With the Inventory Manager
A11: 7 | B11: Borrowing | C11: BR-000001 | D11: General | E11: Borrow test, 2 x Lenovo ThinkPad T14 from Meta / 1A | F11: Cancel request, or approve then return, to release the 2 reserved units
A12: 8 | B12: Requisition state | C12: REQ-000003 | D12: Inv. Manager | E12: IM-approved during testing; now Awaiting approval | F12: Cancel or leave; note it is QA data
A13: 9 | B13: Requisition state | C13: REQ-000005 | D13: Inv. Manager | E13: IM-approved during testing; now Awaiting approval | F13: Cancel or leave; note it is QA data
A14: 10 | B14: Requisition state | C14: REQ-000006 | D14: Inv. Manager | E14: IM-rejected during testing (rejection-path test) | F14: No action - terminal state
A15: 11 | B15: Stock movement | C15: LAP-0001 | D15: Inv. Manager | E15: Issued 2, returned 1 Damaged to Nvidia / 3C, moved 2 from Meta / 1A to Meta / 2A | F15: 1 unit sits in QUARANTINE at Nvidia / 3C and needs releasing; 1 unit still out on BR-000001
A16: 12 | B16: Borrowing | C16: BR-000001 | D16: Inv. Manager | E16: Borrow lifecycle test, now Partly returned | F16: Return the remaining 1 unit to close it out
... A28: 24 | B28: Requisition | C28: REQ-000013 | D28: General | E28: QA-TEST-D014-DATESHIFT — date-shift reproduction, 20 Aug 2026. Deadline entered 2026-08-27, stored 2026-08-26, re-saved without editing the field, now 2026-08-25. One item at 1.00. | F28: Delete draft. Created by the dev team to reproduce D-014, not by the QA session.
